2020-06-30 16:56:27,099 - werkzeug:113 - INFO -  * Running on http://127.0.0.1:5000/ (Press CTRL+C to quit)
2020-06-30 19:26:15,659 - werkzeug:113 - INFO -  * Running on http://127.0.0.1:5000/ (Press CTRL+C to quit)
2020-06-30 19:37:14,144 - werkzeug:113 - INFO -  * Running on http://127.0.0.1:5000/ (Press CTRL+C to quit)
2020-06-30 19:37:24,445 - flask:1892 - ERROR - Exception on /users [GET]
Traceback (most recent call last):
  File "/usr/local/lib/python3.7/site-packages/flask/app.py", line 2447, in wsgi_app
    response = self.full_dispatch_request()
  File "/usr/local/lib/python3.7/site-packages/flask/app.py", line 1953, in full_dispatch_request
    return self.finalize_request(rv)
  File "/usr/local/lib/python3.7/site-packages/flask/app.py", line 1968, in finalize_request
    response = self.make_response(rv)
  File "/usr/local/lib/python3.7/site-packages/flask/app.py", line 2098, in make_response
    "The view function did not return a valid response. The"
TypeError: The view function did not return a valid response. The function either returned None or ended without a return statement.
2020-06-30 19:37:24,448 - werkzeug:113 - INFO - 127.0.0.1 - - [30/Jun/2020 19:37:24] "[35m[1mGET /users HTTP/1.1[0m" 500 -
2020-06-30 19:39:40,997 - werkzeug:113 - INFO -  * Running on http://127.0.0.1:5000/ (Press CTRL+C to quit)
2020-06-30 19:39:59,860 - werkzeug:113 - INFO - 127.0.0.1 - - [30/Jun/2020 19:39:59] "[31m[1mPOST /users HTTP/1.1[0m" 400 -
2020-06-30 19:41:32,666 - werkzeug:113 - INFO -  * Running on http://127.0.0.1:5000/ (Press CTRL+C to quit)
2020-06-30 19:41:40,301 - werkzeug:113 - INFO - 127.0.0.1 - - [30/Jun/2020 19:41:40] "[31m[1mPOST /users HTTP/1.1[0m" 400 -
2020-06-30 19:45:51,154 - werkzeug:113 - INFO -  * Running on http://127.0.0.1:5000/ (Press CTRL+C to quit)
2020-06-30 19:46:01,812 - flask:1892 - ERROR - Exception on /users [POST]
Traceback (most recent call last):
  File "/usr/local/lib/python3.7/site-packages/flask/app.py", line 2447, in wsgi_app
    response = self.full_dispatch_request()
  File "/usr/local/lib/python3.7/site-packages/flask/app.py", line 1952, in full_dispatch_request
    rv = self.handle_user_exception(e)
  File "/usr/local/lib/python3.7/site-packages/flask_cors/extension.py", line 161, in wrapped_function
    return cors_after_request(app.make_response(f(*args, **kwargs)))
  File "/usr/local/lib/python3.7/site-packages/flask/app.py", line 1821, in handle_user_exception
    reraise(exc_type, exc_value, tb)
  File "/usr/local/lib/python3.7/site-packages/flask/_compat.py", line 39, in reraise
    raise value
  File "/usr/local/lib/python3.7/site-packages/flask/app.py", line 1950, in full_dispatch_request
    rv = self.dispatch_request()
  File "/usr/local/lib/python3.7/site-packages/flask/app.py", line 1936, in dispatch_request
    return self.view_functions[rule.endpoint](**req.view_args)
  File "/Users/user/Desktop/projectbackup/SchoolSystem/main.py", line 18, in login
    _log.debug(request.user)
  File "/usr/local/lib/python3.7/site-packages/werkzeug/local.py", line 347, in __getattr__
    return getattr(self._get_current_object(), name)
AttributeError: 'Request' object has no attribute 'user'
2020-06-30 19:46:01,818 - werkzeug:113 - INFO - 127.0.0.1 - - [30/Jun/2020 19:46:01] "[35m[1mPOST /users HTTP/1.1[0m" 500 -
2020-06-30 19:47:50,614 - flask:1892 - ERROR - Exception on /users [POST]
Traceback (most recent call last):
  File "/usr/local/lib/python3.7/site-packages/flask/app.py", line 2447, in wsgi_app
    response = self.full_dispatch_request()
  File "/usr/local/lib/python3.7/site-packages/flask/app.py", line 1952, in full_dispatch_request
    rv = self.handle_user_exception(e)
  File "/usr/local/lib/python3.7/site-packages/flask_cors/extension.py", line 161, in wrapped_function
    return cors_after_request(app.make_response(f(*args, **kwargs)))
  File "/usr/local/lib/python3.7/site-packages/flask/app.py", line 1821, in handle_user_exception
    reraise(exc_type, exc_value, tb)
  File "/usr/local/lib/python3.7/site-packages/flask/_compat.py", line 39, in reraise
    raise value
  File "/usr/local/lib/python3.7/site-packages/flask/app.py", line 1950, in full_dispatch_request
    rv = self.dispatch_request()
  File "/usr/local/lib/python3.7/site-packages/flask/app.py", line 1936, in dispatch_request
    return self.view_functions[rule.endpoint](**req.view_args)
  File "/Users/user/Desktop/projectbackup/SchoolSystem/main.py", line 18, in login
    _log.debug(request.user)
  File "/usr/local/lib/python3.7/site-packages/werkzeug/local.py", line 347, in __getattr__
    return getattr(self._get_current_object(), name)
AttributeError: 'Request' object has no attribute 'user'
2020-06-30 19:47:50,616 - werkzeug:113 - INFO - 127.0.0.1 - - [30/Jun/2020 19:47:50] "[35m[1mPOST /users HTTP/1.1[0m" 500 -
2020-06-30 19:48:43,690 - werkzeug:113 - INFO -  * Running on http://127.0.0.1:5000/ (Press CTRL+C to quit)
2020-06-30 19:48:52,586 - flask:1892 - ERROR - Exception on /users [POST]
Traceback (most recent call last):
  File "/usr/local/lib/python3.7/site-packages/flask/app.py", line 2447, in wsgi_app
    response = self.full_dispatch_request()
  File "/usr/local/lib/python3.7/site-packages/flask/app.py", line 1952, in full_dispatch_request
    rv = self.handle_user_exception(e)
  File "/usr/local/lib/python3.7/site-packages/flask_cors/extension.py", line 161, in wrapped_function
    return cors_after_request(app.make_response(f(*args, **kwargs)))
  File "/usr/local/lib/python3.7/site-packages/flask/app.py", line 1821, in handle_user_exception
    reraise(exc_type, exc_value, tb)
  File "/usr/local/lib/python3.7/site-packages/flask/_compat.py", line 39, in reraise
    raise value
  File "/usr/local/lib/python3.7/site-packages/flask/app.py", line 1950, in full_dispatch_request
    rv = self.dispatch_request()
  File "/usr/local/lib/python3.7/site-packages/flask/app.py", line 1936, in dispatch_request
    return self.view_functions[rule.endpoint](**req.view_args)
  File "/Users/user/Desktop/projectbackup/SchoolSystem/main.py", line 18, in login
    _log.debug(request.body)
  File "/usr/local/lib/python3.7/site-packages/werkzeug/local.py", line 347, in __getattr__
    return getattr(self._get_current_object(), name)
AttributeError: 'Request' object has no attribute 'body'
2020-06-30 19:48:52,589 - werkzeug:113 - INFO - 127.0.0.1 - - [30/Jun/2020 19:48:52] "[35m[1mPOST /users HTTP/1.1[0m" 500 -
2020-06-30 19:50:13,551 - werkzeug:113 - INFO -  * Running on http://127.0.0.1:5000/ (Press CTRL+C to quit)
2020-06-30 19:50:23,824 - SchoolSystem.data.mongo:23 - INFO - Attempting to retrieve user from database
2020-06-30 19:50:23,824 - flask:1892 - ERROR - Exception on /users [POST]
Traceback (most recent call last):
  File "/usr/local/lib/python3.7/site-packages/flask/app.py", line 2447, in wsgi_app
    response = self.full_dispatch_request()
  File "/usr/local/lib/python3.7/site-packages/flask/app.py", line 1952, in full_dispatch_request
    rv = self.handle_user_exception(e)
  File "/usr/local/lib/python3.7/site-packages/flask_cors/extension.py", line 161, in wrapped_function
    return cors_after_request(app.make_response(f(*args, **kwargs)))
  File "/usr/local/lib/python3.7/site-packages/flask/app.py", line 1821, in handle_user_exception
    reraise(exc_type, exc_value, tb)
  File "/usr/local/lib/python3.7/site-packages/flask/_compat.py", line 39, in reraise
    raise value
  File "/usr/local/lib/python3.7/site-packages/flask/app.py", line 1950, in full_dispatch_request
    rv = self.dispatch_request()
  File "/usr/local/lib/python3.7/site-packages/flask/app.py", line 1936, in dispatch_request
    return self.view_functions[rule.endpoint](**req.view_args)
  File "/Users/user/Desktop/projectbackup/SchoolSystem/main.py", line 20, in login
    user = db.login(request.json)
  File "/Users/user/Desktop/projectbackup/SchoolSystem/data/mongo.py", line 24, in login
    username = user.username
AttributeError: 'NoneType' object has no attribute 'username'
2020-06-30 19:50:23,835 - werkzeug:113 - INFO - 127.0.0.1 - - [30/Jun/2020 19:50:23] "[35m[1mPOST /users HTTP/1.1[0m" 500 -
2020-06-30 19:53:32,324 - werkzeug:113 - INFO -  * Running on http://127.0.0.1:5000/ (Press CTRL+C to quit)
2020-06-30 19:53:40,808 - werkzeug:113 - INFO -  * Running on http://127.0.0.1:5000/ (Press CTRL+C to quit)
2020-06-30 19:53:50,118 - flask:1892 - ERROR - Exception on /users [POST]
Traceback (most recent call last):
  File "/usr/local/lib/python3.7/site-packages/flask/app.py", line 2447, in wsgi_app
    response = self.full_dispatch_request()
  File "/usr/local/lib/python3.7/site-packages/flask/app.py", line 1952, in full_dispatch_request
    rv = self.handle_user_exception(e)
  File "/usr/local/lib/python3.7/site-packages/flask_cors/extension.py", line 161, in wrapped_function
    return cors_after_request(app.make_response(f(*args, **kwargs)))
  File "/usr/local/lib/python3.7/site-packages/flask/app.py", line 1821, in handle_user_exception
    reraise(exc_type, exc_value, tb)
  File "/usr/local/lib/python3.7/site-packages/flask/_compat.py", line 39, in reraise
    raise value
  File "/usr/local/lib/python3.7/site-packages/flask/app.py", line 1950, in full_dispatch_request
    rv = self.dispatch_request()
  File "/usr/local/lib/python3.7/site-packages/flask/app.py", line 1936, in dispatch_request
    return self.view_functions[rule.endpoint](**req.view_args)
  File "/Users/user/Desktop/projectbackup/SchoolSystem/main.py", line 18, in login
    _log.debug(req)
NameError: name 'req' is not defined
2020-06-30 19:53:50,122 - werkzeug:113 - INFO - 127.0.0.1 - - [30/Jun/2020 19:53:50] "[35m[1mPOST /users HTTP/1.1[0m" 500 -
2020-06-30 19:57:31,489 - werkzeug:113 - INFO -  * Running on http://127.0.0.1:5000/ (Press CTRL+C to quit)
2020-06-30 19:57:45,364 - SchoolSystem.data.mongo:23 - INFO - Attempting to retrieve user from database
2020-06-30 19:57:45,365 - flask:1892 - ERROR - Exception on /users [POST]
Traceback (most recent call last):
  File "/usr/local/lib/python3.7/site-packages/flask/app.py", line 2447, in wsgi_app
    response = self.full_dispatch_request()
  File "/usr/local/lib/python3.7/site-packages/flask/app.py", line 1952, in full_dispatch_request
    rv = self.handle_user_exception(e)
  File "/usr/local/lib/python3.7/site-packages/flask_cors/extension.py", line 161, in wrapped_function
    return cors_after_request(app.make_response(f(*args, **kwargs)))
  File "/usr/local/lib/python3.7/site-packages/flask/app.py", line 1821, in handle_user_exception
    reraise(exc_type, exc_value, tb)
  File "/usr/local/lib/python3.7/site-packages/flask/_compat.py", line 39, in reraise
    raise value
  File "/usr/local/lib/python3.7/site-packages/flask/app.py", line 1950, in full_dispatch_request
    rv = self.dispatch_request()
  File "/usr/local/lib/python3.7/site-packages/flask/app.py", line 1936, in dispatch_request
    return self.view_functions[rule.endpoint](**req.view_args)
  File "/Users/user/Desktop/projectbackup/SchoolSystem/main.py", line 20, in login
    user = db.login(request.data)
  File "/Users/user/Desktop/projectbackup/SchoolSystem/data/mongo.py", line 24, in login
    username = user.username
AttributeError: 'bytes' object has no attribute 'username'
2020-06-30 19:57:45,375 - werkzeug:113 - INFO - 127.0.0.1 - - [30/Jun/2020 19:57:45] "[35m[1mPOST /users HTTP/1.1[0m" 500 -
2020-06-30 19:59:59,495 - werkzeug:113 - INFO -  * Running on http://127.0.0.1:5000/ (Press CTRL+C to quit)
2020-06-30 20:00:06,844 - SchoolSystem.data.mongo:23 - INFO - Attempting to retrieve user from database
2020-06-30 20:00:06,844 - flask:1892 - ERROR - Exception on /users [POST]
Traceback (most recent call last):
  File "/usr/local/lib/python3.7/site-packages/flask/app.py", line 2447, in wsgi_app
    response = self.full_dispatch_request()
  File "/usr/local/lib/python3.7/site-packages/flask/app.py", line 1952, in full_dispatch_request
    rv = self.handle_user_exception(e)
  File "/usr/local/lib/python3.7/site-packages/flask_cors/extension.py", line 161, in wrapped_function
    return cors_after_request(app.make_response(f(*args, **kwargs)))
  File "/usr/local/lib/python3.7/site-packages/flask/app.py", line 1821, in handle_user_exception
    reraise(exc_type, exc_value, tb)
  File "/usr/local/lib/python3.7/site-packages/flask/_compat.py", line 39, in reraise
    raise value
  File "/usr/local/lib/python3.7/site-packages/flask/app.py", line 1950, in full_dispatch_request
    rv = self.dispatch_request()
  File "/usr/local/lib/python3.7/site-packages/flask/app.py", line 1936, in dispatch_request
    return self.view_functions[rule.endpoint](**req.view_args)
  File "/Users/user/Desktop/projectbackup/SchoolSystem/main.py", line 20, in login
    user = db.login(request.data)
  File "/Users/user/Desktop/projectbackup/SchoolSystem/data/mongo.py", line 24, in login
    username = user.username
AttributeError: 'bytes' object has no attribute 'username'
2020-06-30 20:00:06,846 - werkzeug:113 - INFO - 127.0.0.1 - - [30/Jun/2020 20:00:06] "[35m[1mPOST /users HTTP/1.1[0m" 500 -
2020-06-30 20:05:05,504 - werkzeug:113 - INFO -  * Running on http://127.0.0.1:5000/ (Press CTRL+C to quit)
2020-06-30 20:05:11,963 - SchoolSystem.data.mongo:23 - INFO - Attempting to retrieve user from database
2020-06-30 20:05:11,964 - flask:1892 - ERROR - Exception on /users [POST]
Traceback (most recent call last):
  File "/usr/local/lib/python3.7/site-packages/flask/app.py", line 2447, in wsgi_app
    response = self.full_dispatch_request()
  File "/usr/local/lib/python3.7/site-packages/flask/app.py", line 1952, in full_dispatch_request
    rv = self.handle_user_exception(e)
  File "/usr/local/lib/python3.7/site-packages/flask_cors/extension.py", line 161, in wrapped_function
    return cors_after_request(app.make_response(f(*args, **kwargs)))
  File "/usr/local/lib/python3.7/site-packages/flask/app.py", line 1821, in handle_user_exception
    reraise(exc_type, exc_value, tb)
  File "/usr/local/lib/python3.7/site-packages/flask/_compat.py", line 39, in reraise
    raise value
  File "/usr/local/lib/python3.7/site-packages/flask/app.py", line 1950, in full_dispatch_request
    rv = self.dispatch_request()
  File "/usr/local/lib/python3.7/site-packages/flask/app.py", line 1936, in dispatch_request
    return self.view_functions[rule.endpoint](**req.view_args)
  File "/Users/user/Desktop/projectbackup/SchoolSystem/main.py", line 20, in login
    user = db.login(request.data)
  File "/Users/user/Desktop/projectbackup/SchoolSystem/data/mongo.py", line 24, in login
    username = user.username
AttributeError: 'bytes' object has no attribute 'username'
2020-06-30 20:05:11,966 - werkzeug:113 - INFO - 127.0.0.1 - - [30/Jun/2020 20:05:11] "[35m[1mPOST /users HTTP/1.1[0m" 500 -
2020-06-30 20:07:09,727 - werkzeug:113 - INFO -  * Running on http://127.0.0.1:5000/ (Press CTRL+C to quit)
2020-06-30 20:07:17,425 - SchoolSystem.data.mongo:23 - INFO - Attempting to retrieve user from database
2020-06-30 20:07:17,425 - flask:1892 - ERROR - Exception on /users [POST]
Traceback (most recent call last):
  File "/usr/local/lib/python3.7/site-packages/flask/app.py", line 2447, in wsgi_app
    response = self.full_dispatch_request()
  File "/usr/local/lib/python3.7/site-packages/flask/app.py", line 1952, in full_dispatch_request
    rv = self.handle_user_exception(e)
  File "/usr/local/lib/python3.7/site-packages/flask_cors/extension.py", line 161, in wrapped_function
    return cors_after_request(app.make_response(f(*args, **kwargs)))
  File "/usr/local/lib/python3.7/site-packages/flask/app.py", line 1821, in handle_user_exception
    reraise(exc_type, exc_value, tb)
  File "/usr/local/lib/python3.7/site-packages/flask/_compat.py", line 39, in reraise
    raise value
  File "/usr/local/lib/python3.7/site-packages/flask/app.py", line 1950, in full_dispatch_request
    rv = self.dispatch_request()
  File "/usr/local/lib/python3.7/site-packages/flask/app.py", line 1936, in dispatch_request
    return self.view_functions[rule.endpoint](**req.view_args)
  File "/Users/user/Desktop/projectbackup/SchoolSystem/main.py", line 20, in login
    user = db.login(request.data)
  File "/Users/user/Desktop/projectbackup/SchoolSystem/data/mongo.py", line 24, in login
    username = user.username
AttributeError: 'bytes' object has no attribute 'username'
2020-06-30 20:07:17,428 - werkzeug:113 - INFO - 127.0.0.1 - - [30/Jun/2020 20:07:17] "[35m[1mPOST /users HTTP/1.1[0m" 500 -
2020-06-30 20:07:31,145 - SchoolSystem.data.mongo:23 - INFO - Attempting to retrieve user from database
2020-06-30 20:07:31,145 - flask:1892 - ERROR - Exception on /users [POST]
Traceback (most recent call last):
  File "/usr/local/lib/python3.7/site-packages/flask/app.py", line 2447, in wsgi_app
    response = self.full_dispatch_request()
  File "/usr/local/lib/python3.7/site-packages/flask/app.py", line 1952, in full_dispatch_request
    rv = self.handle_user_exception(e)
  File "/usr/local/lib/python3.7/site-packages/flask_cors/extension.py", line 161, in wrapped_function
    return cors_after_request(app.make_response(f(*args, **kwargs)))
  File "/usr/local/lib/python3.7/site-packages/flask/app.py", line 1821, in handle_user_exception
    reraise(exc_type, exc_value, tb)
  File "/usr/local/lib/python3.7/site-packages/flask/_compat.py", line 39, in reraise
    raise value
  File "/usr/local/lib/python3.7/site-packages/flask/app.py", line 1950, in full_dispatch_request
    rv = self.dispatch_request()
  File "/usr/local/lib/python3.7/site-packages/flask/app.py", line 1936, in dispatch_request
    return self.view_functions[rule.endpoint](**req.view_args)
  File "/Users/user/Desktop/projectbackup/SchoolSystem/main.py", line 20, in login
    user = db.login(request.data)
  File "/Users/user/Desktop/projectbackup/SchoolSystem/data/mongo.py", line 24, in login
    username = user.username
AttributeError: 'bytes' object has no attribute 'username'
2020-06-30 20:07:31,146 - werkzeug:113 - INFO - 127.0.0.1 - - [30/Jun/2020 20:07:31] "[35m[1mPOST /users HTTP/1.1[0m" 500 -
2020-06-30 20:09:06,536 - werkzeug:113 - INFO -  * Running on http://127.0.0.1:5000/ (Press CTRL+C to quit)
2020-06-30 20:09:12,872 - werkzeug:113 - INFO - 127.0.0.1 - - [30/Jun/2020 20:09:12] "[37mOPTIONS /users HTTP/1.1[0m" 200 -
2020-06-30 20:09:12,874 - SchoolSystem.data.mongo:23 - INFO - Attempting to retrieve user from database
2020-06-30 20:09:12,874 - flask:1892 - ERROR - Exception on /users [POST]
Traceback (most recent call last):
  File "/usr/local/lib/python3.7/site-packages/flask/app.py", line 2447, in wsgi_app
    response = self.full_dispatch_request()
  File "/usr/local/lib/python3.7/site-packages/flask/app.py", line 1952, in full_dispatch_request
    rv = self.handle_user_exception(e)
  File "/usr/local/lib/python3.7/site-packages/flask_cors/extension.py", line 161, in wrapped_function
    return cors_after_request(app.make_response(f(*args, **kwargs)))
  File "/usr/local/lib/python3.7/site-packages/flask/app.py", line 1821, in handle_user_exception
    reraise(exc_type, exc_value, tb)
  File "/usr/local/lib/python3.7/site-packages/flask/_compat.py", line 39, in reraise
    raise value
  File "/usr/local/lib/python3.7/site-packages/flask/app.py", line 1950, in full_dispatch_request
    rv = self.dispatch_request()
  File "/usr/local/lib/python3.7/site-packages/flask/app.py", line 1936, in dispatch_request
    return self.view_functions[rule.endpoint](**req.view_args)
  File "/Users/user/Desktop/projectbackup/SchoolSystem/main.py", line 20, in login
    user = db.login(request.data)
  File "/Users/user/Desktop/projectbackup/SchoolSystem/data/mongo.py", line 24, in login
    username = user.username
AttributeError: 'bytes' object has no attribute 'username'
2020-06-30 20:09:12,885 - werkzeug:113 - INFO - 127.0.0.1 - - [30/Jun/2020 20:09:12] "[35m[1mPOST /users HTTP/1.1[0m" 500 -
2020-06-30 20:12:59,662 - werkzeug:113 - INFO -  * Running on http://127.0.0.1:5000/ (Press CTRL+C to quit)
2020-06-30 20:13:07,009 - werkzeug:113 - INFO - 127.0.0.1 - - [30/Jun/2020 20:13:07] "[37mOPTIONS /users HTTP/1.1[0m" 200 -
2020-06-30 20:13:07,011 - SchoolSystem.data.mongo:23 - INFO - Attempting to retrieve user from database
2020-06-30 20:13:07,012 - flask:1892 - ERROR - Exception on /users [POST]
Traceback (most recent call last):
  File "/usr/local/lib/python3.7/site-packages/flask/app.py", line 2447, in wsgi_app
    response = self.full_dispatch_request()
  File "/usr/local/lib/python3.7/site-packages/flask/app.py", line 1952, in full_dispatch_request
    rv = self.handle_user_exception(e)
  File "/usr/local/lib/python3.7/site-packages/flask_cors/extension.py", line 161, in wrapped_function
    return cors_after_request(app.make_response(f(*args, **kwargs)))
  File "/usr/local/lib/python3.7/site-packages/flask/app.py", line 1821, in handle_user_exception
    reraise(exc_type, exc_value, tb)
  File "/usr/local/lib/python3.7/site-packages/flask/_compat.py", line 39, in reraise
    raise value
  File "/usr/local/lib/python3.7/site-packages/flask/app.py", line 1950, in full_dispatch_request
    rv = self.dispatch_request()
  File "/usr/local/lib/python3.7/site-packages/flask/app.py", line 1936, in dispatch_request
    return self.view_functions[rule.endpoint](**req.view_args)
  File "/Users/user/Desktop/projectbackup/SchoolSystem/main.py", line 20, in login
    user = db.login(request.data.decode('utf-8'))
  File "/Users/user/Desktop/projectbackup/SchoolSystem/data/mongo.py", line 24, in login
    username = user.username
AttributeError: 'str' object has no attribute 'username'
2020-06-30 20:13:07,024 - werkzeug:113 - INFO - 127.0.0.1 - - [30/Jun/2020 20:13:07] "[35m[1mPOST /users HTTP/1.1[0m" 500 -
2020-06-30 20:15:32,063 - werkzeug:113 - INFO -  * Running on http://127.0.0.1:5000/ (Press CTRL+C to quit)
2020-06-30 20:15:37,936 - werkzeug:113 - INFO - 127.0.0.1 - - [30/Jun/2020 20:15:37] "[37mOPTIONS /users HTTP/1.1[0m" 200 -
2020-06-30 20:15:37,938 - SchoolSystem.data.mongo:23 - INFO - Attempting to retrieve user from database
2020-06-30 20:15:37,938 - flask:1892 - ERROR - Exception on /users [POST]
Traceback (most recent call last):
  File "/usr/local/lib/python3.7/site-packages/flask/app.py", line 2447, in wsgi_app
    response = self.full_dispatch_request()
  File "/usr/local/lib/python3.7/site-packages/flask/app.py", line 1952, in full_dispatch_request
    rv = self.handle_user_exception(e)
  File "/usr/local/lib/python3.7/site-packages/flask_cors/extension.py", line 161, in wrapped_function
    return cors_after_request(app.make_response(f(*args, **kwargs)))
  File "/usr/local/lib/python3.7/site-packages/flask/app.py", line 1821, in handle_user_exception
    reraise(exc_type, exc_value, tb)
  File "/usr/local/lib/python3.7/site-packages/flask/_compat.py", line 39, in reraise
    raise value
  File "/usr/local/lib/python3.7/site-packages/flask/app.py", line 1950, in full_dispatch_request
    rv = self.dispatch_request()
  File "/usr/local/lib/python3.7/site-packages/flask/app.py", line 1936, in dispatch_request
    return self.view_functions[rule.endpoint](**req.view_args)
  File "/Users/user/Desktop/projectbackup/SchoolSystem/main.py", line 21, in login
    user = db.login(temp)
  File "/Users/user/Desktop/projectbackup/SchoolSystem/data/mongo.py", line 24, in login
    username = user.username
AttributeError: 'Response' object has no attribute 'username'
2020-06-30 20:15:37,945 - werkzeug:113 - INFO - 127.0.0.1 - - [30/Jun/2020 20:15:37] "[35m[1mPOST /users HTTP/1.1[0m" 500 -
2020-06-30 20:17:10,680 - werkzeug:113 - INFO -  * Running on http://127.0.0.1:5000/ (Press CTRL+C to quit)
2020-06-30 20:17:16,795 - werkzeug:113 - INFO - 127.0.0.1 - - [30/Jun/2020 20:17:16] "[37mOPTIONS /users HTTP/1.1[0m" 200 -
2020-06-30 20:17:16,797 - flask:1892 - ERROR - Exception on /users [POST]
Traceback (most recent call last):
  File "/usr/local/lib/python3.7/site-packages/flask/app.py", line 2447, in wsgi_app
    response = self.full_dispatch_request()
  File "/usr/local/lib/python3.7/site-packages/flask/app.py", line 1952, in full_dispatch_request
    rv = self.handle_user_exception(e)
  File "/usr/local/lib/python3.7/site-packages/flask_cors/extension.py", line 161, in wrapped_function
    return cors_after_request(app.make_response(f(*args, **kwargs)))
  File "/usr/local/lib/python3.7/site-packages/flask/app.py", line 1821, in handle_user_exception
    reraise(exc_type, exc_value, tb)
  File "/usr/local/lib/python3.7/site-packages/flask/_compat.py", line 39, in reraise
    raise value
  File "/usr/local/lib/python3.7/site-packages/flask/app.py", line 1950, in full_dispatch_request
    rv = self.dispatch_request()
  File "/usr/local/lib/python3.7/site-packages/flask/app.py", line 1936, in dispatch_request
    return self.view_functions[rule.endpoint](**req.view_args)
  File "/Users/user/Desktop/projectbackup/SchoolSystem/main.py", line 20, in login
    vary = temp['username']
TypeError: 'Response' object is not subscriptable
2020-06-30 20:17:16,804 - werkzeug:113 - INFO - 127.0.0.1 - - [30/Jun/2020 20:17:16] "[35m[1mPOST /users HTTP/1.1[0m" 500 -
2020-06-30 20:18:31,344 - werkzeug:113 - INFO - 127.0.0.1 - - [30/Jun/2020 20:18:31] "[37mOPTIONS /users HTTP/1.1[0m" 200 -
2020-06-30 20:18:31,347 - flask:1892 - ERROR - Exception on /users [POST]
Traceback (most recent call last):
  File "/usr/local/lib/python3.7/site-packages/flask/app.py", line 2447, in wsgi_app
    response = self.full_dispatch_request()
  File "/usr/local/lib/python3.7/site-packages/flask/app.py", line 1952, in full_dispatch_request
    rv = self.handle_user_exception(e)
  File "/usr/local/lib/python3.7/site-packages/flask_cors/extension.py", line 161, in wrapped_function
    return cors_after_request(app.make_response(f(*args, **kwargs)))
  File "/usr/local/lib/python3.7/site-packages/flask/app.py", line 1821, in handle_user_exception
    reraise(exc_type, exc_value, tb)
  File "/usr/local/lib/python3.7/site-packages/flask/_compat.py", line 39, in reraise
    raise value
  File "/usr/local/lib/python3.7/site-packages/flask/app.py", line 1950, in full_dispatch_request
    rv = self.dispatch_request()
  File "/usr/local/lib/python3.7/site-packages/flask/app.py", line 1936, in dispatch_request
    return self.view_functions[rule.endpoint](**req.view_args)
  File "/Users/user/Desktop/projectbackup/SchoolSystem/main.py", line 20, in login
    vary = temp['username']
TypeError: 'Response' object is not subscriptable
2020-06-30 20:18:31,354 - werkzeug:113 - INFO - 127.0.0.1 - - [30/Jun/2020 20:18:31] "[35m[1mPOST /users HTTP/1.1[0m" 500 -
2020-06-30 20:19:18,864 - werkzeug:113 - INFO -  * Running on http://127.0.0.1:5000/ (Press CTRL+C to quit)
2020-06-30 20:19:25,935 - werkzeug:113 - INFO - 127.0.0.1 - - [30/Jun/2020 20:19:25] "[37mOPTIONS /users HTTP/1.1[0m" 200 -
2020-06-30 20:19:25,938 - SchoolSystem.data.mongo:23 - INFO - Attempting to retrieve user from database
2020-06-30 20:19:25,938 - flask:1892 - ERROR - Exception on /users [POST]
Traceback (most recent call last):
  File "/usr/local/lib/python3.7/site-packages/flask/app.py", line 2447, in wsgi_app
    response = self.full_dispatch_request()
  File "/usr/local/lib/python3.7/site-packages/flask/app.py", line 1952, in full_dispatch_request
    rv = self.handle_user_exception(e)
  File "/usr/local/lib/python3.7/site-packages/flask_cors/extension.py", line 161, in wrapped_function
    return cors_after_request(app.make_response(f(*args, **kwargs)))
  File "/usr/local/lib/python3.7/site-packages/flask/app.py", line 1821, in handle_user_exception
    reraise(exc_type, exc_value, tb)
  File "/usr/local/lib/python3.7/site-packages/flask/_compat.py", line 39, in reraise
    raise value
  File "/usr/local/lib/python3.7/site-packages/flask/app.py", line 1950, in full_dispatch_request
    rv = self.dispatch_request()
  File "/usr/local/lib/python3.7/site-packages/flask/app.py", line 1936, in dispatch_request
    return self.view_functions[rule.endpoint](**req.view_args)
  File "/Users/user/Desktop/projectbackup/SchoolSystem/main.py", line 21, in login
    user = db.login(temp)
  File "/Users/user/Desktop/projectbackup/SchoolSystem/data/mongo.py", line 24, in login
    username = user.username
AttributeError: 'Response' object has no attribute 'username'
2020-06-30 20:19:25,947 - werkzeug:113 - INFO - 127.0.0.1 - - [30/Jun/2020 20:19:25] "[35m[1mPOST /users HTTP/1.1[0m" 500 -
2020-06-30 20:21:22,522 - werkzeug:113 - INFO -  * Running on http://127.0.0.1:5000/ (Press CTRL+C to quit)
2020-06-30 20:21:28,496 - werkzeug:113 - INFO - 127.0.0.1 - - [30/Jun/2020 20:21:28] "[37mOPTIONS /users HTTP/1.1[0m" 200 -
2020-06-30 20:21:28,498 - SchoolSystem.data.mongo:23 - INFO - Attempting to retrieve user from database
2020-06-30 20:21:28,498 - flask:1892 - ERROR - Exception on /users [POST]
Traceback (most recent call last):
  File "/usr/local/lib/python3.7/site-packages/flask/app.py", line 2447, in wsgi_app
    response = self.full_dispatch_request()
  File "/usr/local/lib/python3.7/site-packages/flask/app.py", line 1952, in full_dispatch_request
    rv = self.handle_user_exception(e)
  File "/usr/local/lib/python3.7/site-packages/flask_cors/extension.py", line 161, in wrapped_function
    return cors_after_request(app.make_response(f(*args, **kwargs)))
  File "/usr/local/lib/python3.7/site-packages/flask/app.py", line 1821, in handle_user_exception
    reraise(exc_type, exc_value, tb)
  File "/usr/local/lib/python3.7/site-packages/flask/_compat.py", line 39, in reraise
    raise value
  File "/usr/local/lib/python3.7/site-packages/flask/app.py", line 1950, in full_dispatch_request
    rv = self.dispatch_request()
  File "/usr/local/lib/python3.7/site-packages/flask/app.py", line 1936, in dispatch_request
    return self.view_functions[rule.endpoint](**req.view_args)
  File "/Users/user/Desktop/projectbackup/SchoolSystem/main.py", line 21, in login
    user = db.login(temp)
  File "/Users/user/Desktop/projectbackup/SchoolSystem/data/mongo.py", line 24, in login
    username = user.username
AttributeError: 'str' object has no attribute 'username'
2020-06-30 20:21:28,506 - werkzeug:113 - INFO - 127.0.0.1 - - [30/Jun/2020 20:21:28] "[35m[1mPOST /users HTTP/1.1[0m" 500 -
2020-06-30 20:23:48,627 - werkzeug:113 - INFO -  * Running on http://127.0.0.1:5000/ (Press CTRL+C to quit)
2020-06-30 20:23:55,178 - werkzeug:113 - INFO - 127.0.0.1 - - [30/Jun/2020 20:23:55] "[37mOPTIONS /users HTTP/1.1[0m" 200 -
2020-06-30 20:23:55,181 - flask:1892 - ERROR - Exception on /users [POST]
Traceback (most recent call last):
  File "/usr/local/lib/python3.7/site-packages/flask/app.py", line 2447, in wsgi_app
    response = self.full_dispatch_request()
  File "/usr/local/lib/python3.7/site-packages/flask/app.py", line 1952, in full_dispatch_request
    rv = self.handle_user_exception(e)
  File "/usr/local/lib/python3.7/site-packages/flask_cors/extension.py", line 161, in wrapped_function
    return cors_after_request(app.make_response(f(*args, **kwargs)))
  File "/usr/local/lib/python3.7/site-packages/flask/app.py", line 1821, in handle_user_exception
    reraise(exc_type, exc_value, tb)
  File "/usr/local/lib/python3.7/site-packages/flask/_compat.py", line 39, in reraise
    raise value
  File "/usr/local/lib/python3.7/site-packages/flask/app.py", line 1950, in full_dispatch_request
    rv = self.dispatch_request()
  File "/usr/local/lib/python3.7/site-packages/flask/app.py", line 1936, in dispatch_request
    return self.view_functions[rule.endpoint](**req.view_args)
  File "/Users/user/Desktop/projectbackup/SchoolSystem/main.py", line 20, in login
    _log.debug(temp.__dict__)
AttributeError: 'str' object has no attribute '__dict__'
2020-06-30 20:23:55,188 - werkzeug:113 - INFO - 127.0.0.1 - - [30/Jun/2020 20:23:55] "[35m[1mPOST /users HTTP/1.1[0m" 500 -
2020-06-30 20:25:25,356 - werkzeug:113 - INFO -  * Running on http://127.0.0.1:5000/ (Press CTRL+C to quit)
2020-06-30 20:25:31,752 - werkzeug:113 - INFO - 127.0.0.1 - - [30/Jun/2020 20:25:31] "[37mOPTIONS /users HTTP/1.1[0m" 200 -
2020-06-30 20:25:31,755 - SchoolSystem.data.mongo:23 - INFO - Attempting to retrieve user from database
2020-06-30 20:25:31,755 - flask:1892 - ERROR - Exception on /users [POST]
Traceback (most recent call last):
  File "/usr/local/lib/python3.7/site-packages/flask/app.py", line 2447, in wsgi_app
    response = self.full_dispatch_request()
  File "/usr/local/lib/python3.7/site-packages/flask/app.py", line 1952, in full_dispatch_request
    rv = self.handle_user_exception(e)
  File "/usr/local/lib/python3.7/site-packages/flask_cors/extension.py", line 161, in wrapped_function
    return cors_after_request(app.make_response(f(*args, **kwargs)))
  File "/usr/local/lib/python3.7/site-packages/flask/app.py", line 1821, in handle_user_exception
    reraise(exc_type, exc_value, tb)
  File "/usr/local/lib/python3.7/site-packages/flask/_compat.py", line 39, in reraise
    raise value
  File "/usr/local/lib/python3.7/site-packages/flask/app.py", line 1950, in full_dispatch_request
    rv = self.dispatch_request()
  File "/usr/local/lib/python3.7/site-packages/flask/app.py", line 1936, in dispatch_request
    return self.view_functions[rule.endpoint](**req.view_args)
  File "/Users/user/Desktop/projectbackup/SchoolSystem/main.py", line 21, in login
    user = db.login(temp)
  File "/Users/user/Desktop/projectbackup/SchoolSystem/data/mongo.py", line 24, in login
    username = user.username
AttributeError: 'bytes' object has no attribute 'username'
2020-06-30 20:25:31,763 - werkzeug:113 - INFO - 127.0.0.1 - - [30/Jun/2020 20:25:31] "[35m[1mPOST /users HTTP/1.1[0m" 500 -
2020-06-30 20:27:09,974 - werkzeug:113 - INFO -  * Running on http://127.0.0.1:5000/ (Press CTRL+C to quit)
2020-06-30 20:27:19,232 - werkzeug:113 - INFO - 127.0.0.1 - - [30/Jun/2020 20:27:19] "[37mOPTIONS /users HTTP/1.1[0m" 200 -
2020-06-30 20:27:19,234 - SchoolSystem.data.mongo:23 - INFO - Attempting to retrieve user from database
2020-06-30 20:27:19,235 - flask:1892 - ERROR - Exception on /users [POST]
Traceback (most recent call last):
  File "/usr/local/lib/python3.7/site-packages/flask/app.py", line 2447, in wsgi_app
    response = self.full_dispatch_request()
  File "/usr/local/lib/python3.7/site-packages/flask/app.py", line 1952, in full_dispatch_request
    rv = self.handle_user_exception(e)
  File "/usr/local/lib/python3.7/site-packages/flask_cors/extension.py", line 161, in wrapped_function
    return cors_after_request(app.make_response(f(*args, **kwargs)))
  File "/usr/local/lib/python3.7/site-packages/flask/app.py", line 1821, in handle_user_exception
    reraise(exc_type, exc_value, tb)
  File "/usr/local/lib/python3.7/site-packages/flask/_compat.py", line 39, in reraise
    raise value
  File "/usr/local/lib/python3.7/site-packages/flask/app.py", line 1950, in full_dispatch_request
    rv = self.dispatch_request()
  File "/usr/local/lib/python3.7/site-packages/flask/app.py", line 1936, in dispatch_request
    return self.view_functions[rule.endpoint](**req.view_args)
  File "/Users/user/Desktop/projectbackup/SchoolSystem/main.py", line 21, in login
    user = db.login(temp.__dict__)
  File "/Users/user/Desktop/projectbackup/SchoolSystem/data/mongo.py", line 24, in login
    username = user.username
AttributeError: 'dict' object has no attribute 'username'
2020-06-30 20:27:19,243 - werkzeug:113 - INFO - 127.0.0.1 - - [30/Jun/2020 20:27:19] "[35m[1mPOST /users HTTP/1.1[0m" 500 -
2020-06-30 20:29:32,081 - werkzeug:113 - INFO -  * Running on http://127.0.0.1:5000/ (Press CTRL+C to quit)
2020-06-30 20:29:44,583 - werkzeug:113 - INFO - 127.0.0.1 - - [30/Jun/2020 20:29:44] "[37mOPTIONS /users HTTP/1.1[0m" 200 -
2020-06-30 20:29:44,587 - flask:1892 - ERROR - Exception on /users [POST]
Traceback (most recent call last):
  File "/usr/local/lib/python3.7/site-packages/flask/app.py", line 2447, in wsgi_app
    response = self.full_dispatch_request()
  File "/usr/local/lib/python3.7/site-packages/flask/app.py", line 1952, in full_dispatch_request
    rv = self.handle_user_exception(e)
  File "/usr/local/lib/python3.7/site-packages/flask_cors/extension.py", line 161, in wrapped_function
    return cors_after_request(app.make_response(f(*args, **kwargs)))
  File "/usr/local/lib/python3.7/site-packages/flask/app.py", line 1821, in handle_user_exception
    reraise(exc_type, exc_value, tb)
  File "/usr/local/lib/python3.7/site-packages/flask/_compat.py", line 39, in reraise
    raise value
  File "/usr/local/lib/python3.7/site-packages/flask/app.py", line 1950, in full_dispatch_request
    rv = self.dispatch_request()
  File "/usr/local/lib/python3.7/site-packages/flask/app.py", line 1936, in dispatch_request
    return self.view_functions[rule.endpoint](**req.view_args)
  File "/Users/user/Desktop/projectbackup/SchoolSystem/main.py", line 18, in login
    _log.debug(jsonify(request.form.decode('utf-8')))
AttributeError: 'ImmutableMultiDict' object has no attribute 'decode'
2020-06-30 20:29:44,593 - werkzeug:113 - INFO - 127.0.0.1 - - [30/Jun/2020 20:29:44] "[35m[1mPOST /users HTTP/1.1[0m" 500 -
2020-06-30 20:30:27,878 - werkzeug:113 - INFO -  * Running on http://127.0.0.1:5000/ (Press CTRL+C to quit)
2020-06-30 20:30:34,967 - werkzeug:113 - INFO - 127.0.0.1 - - [30/Jun/2020 20:30:34] "[37mOPTIONS /users HTTP/1.1[0m" 200 -
2020-06-30 20:30:34,970 - SchoolSystem.data.mongo:23 - INFO - Attempting to retrieve user from database
2020-06-30 20:30:34,970 - flask:1892 - ERROR - Exception on /users [POST]
Traceback (most recent call last):
  File "/usr/local/lib/python3.7/site-packages/flask/app.py", line 2447, in wsgi_app
    response = self.full_dispatch_request()
  File "/usr/local/lib/python3.7/site-packages/flask/app.py", line 1952, in full_dispatch_request
    rv = self.handle_user_exception(e)
  File "/usr/local/lib/python3.7/site-packages/flask_cors/extension.py", line 161, in wrapped_function
    return cors_after_request(app.make_response(f(*args, **kwargs)))
  File "/usr/local/lib/python3.7/site-packages/flask/app.py", line 1821, in handle_user_exception
    reraise(exc_type, exc_value, tb)
  File "/usr/local/lib/python3.7/site-packages/flask/_compat.py", line 39, in reraise
    raise value
  File "/usr/local/lib/python3.7/site-packages/flask/app.py", line 1950, in full_dispatch_request
    rv = self.dispatch_request()
  File "/usr/local/lib/python3.7/site-packages/flask/app.py", line 1936, in dispatch_request
    return self.view_functions[rule.endpoint](**req.view_args)
  File "/Users/user/Desktop/projectbackup/SchoolSystem/main.py", line 21, in login
    user = db.login(temp.__dict__)
  File "/Users/user/Desktop/projectbackup/SchoolSystem/data/mongo.py", line 24, in login
    username = user.username
AttributeError: 'dict' object has no attribute 'username'
2020-06-30 20:30:34,977 - werkzeug:113 - INFO - 127.0.0.1 - - [30/Jun/2020 20:30:34] "[35m[1mPOST /users HTTP/1.1[0m" 500 -
2020-06-30 20:39:35,436 - werkzeug:113 - INFO -  * Running on http://127.0.0.1:5000/ (Press CTRL+C to quit)
2020-06-30 20:39:45,953 - werkzeug:113 - INFO - 127.0.0.1 - - [30/Jun/2020 20:39:45] "[37mOPTIONS /users HTTP/1.1[0m" 200 -
2020-06-30 20:39:45,955 - flask:1892 - ERROR - Exception on /users [POST]
Traceback (most recent call last):
  File "/usr/local/lib/python3.7/site-packages/flask/app.py", line 2447, in wsgi_app
    response = self.full_dispatch_request()
  File "/usr/local/lib/python3.7/site-packages/flask/app.py", line 1952, in full_dispatch_request
    rv = self.handle_user_exception(e)
  File "/usr/local/lib/python3.7/site-packages/flask_cors/extension.py", line 161, in wrapped_function
    return cors_after_request(app.make_response(f(*args, **kwargs)))
  File "/usr/local/lib/python3.7/site-packages/flask/app.py", line 1821, in handle_user_exception
    reraise(exc_type, exc_value, tb)
  File "/usr/local/lib/python3.7/site-packages/flask/_compat.py", line 39, in reraise
    raise value
  File "/usr/local/lib/python3.7/site-packages/flask/app.py", line 1950, in full_dispatch_request
    rv = self.dispatch_request()
  File "/usr/local/lib/python3.7/site-packages/flask/app.py", line 1936, in dispatch_request
    return self.view_functions[rule.endpoint](**req.view_args)
  File "/Users/user/Desktop/projectbackup/SchoolSystem/main.py", line 18, in login
    _log.debug((request.form.get_json()))
AttributeError: 'ImmutableMultiDict' object has no attribute 'get_json'
2020-06-30 20:39:45,963 - werkzeug:113 - INFO - 127.0.0.1 - - [30/Jun/2020 20:39:45] "[35m[1mPOST /users HTTP/1.1[0m" 500 -
2020-06-30 20:40:53,119 - werkzeug:113 - INFO -  * Running on http://127.0.0.1:5000/ (Press CTRL+C to quit)
2020-06-30 20:41:03,773 - werkzeug:113 - INFO - 127.0.0.1 - - [30/Jun/2020 20:41:03] "[37mOPTIONS /users HTTP/1.1[0m" 200 -
2020-06-30 20:41:03,776 - flask:1892 - ERROR - Exception on /users [POST]
Traceback (most recent call last):
  File "/usr/local/lib/python3.7/site-packages/flask/app.py", line 2447, in wsgi_app
    response = self.full_dispatch_request()
  File "/usr/local/lib/python3.7/site-packages/flask/app.py", line 1952, in full_dispatch_request
    rv = self.handle_user_exception(e)
  File "/usr/local/lib/python3.7/site-packages/flask_cors/extension.py", line 161, in wrapped_function
    return cors_after_request(app.make_response(f(*args, **kwargs)))
  File "/usr/local/lib/python3.7/site-packages/flask/app.py", line 1821, in handle_user_exception
    reraise(exc_type, exc_value, tb)
  File "/usr/local/lib/python3.7/site-packages/flask/_compat.py", line 39, in reraise
    raise value
  File "/usr/local/lib/python3.7/site-packages/flask/app.py", line 1950, in full_dispatch_request
    rv = self.dispatch_request()
  File "/usr/local/lib/python3.7/site-packages/flask/app.py", line 1936, in dispatch_request
    return self.view_functions[rule.endpoint](**req.view_args)
  File "/Users/user/Desktop/projectbackup/SchoolSystem/main.py", line 20, in login
    _log.debug(temp.__dict__)
AttributeError: 'str' object has no attribute '__dict__'
2020-06-30 20:41:03,783 - werkzeug:113 - INFO - 127.0.0.1 - - [30/Jun/2020 20:41:03] "[35m[1mPOST /users HTTP/1.1[0m" 500 -
2020-06-30 20:41:39,842 - werkzeug:113 - INFO -  * Running on http://127.0.0.1:5000/ (Press CTRL+C to quit)
2020-06-30 20:41:49,502 - werkzeug:113 - INFO - 127.0.0.1 - - [30/Jun/2020 20:41:49] "[37mOPTIONS /users HTTP/1.1[0m" 200 -
2020-06-30 20:41:49,505 - SchoolSystem.data.mongo:23 - INFO - Attempting to retrieve user from database
2020-06-30 20:41:49,505 - flask:1892 - ERROR - Exception on /users [POST]
Traceback (most recent call last):
  File "/usr/local/lib/python3.7/site-packages/flask/app.py", line 2447, in wsgi_app
    response = self.full_dispatch_request()
  File "/usr/local/lib/python3.7/site-packages/flask/app.py", line 1952, in full_dispatch_request
    rv = self.handle_user_exception(e)
  File "/usr/local/lib/python3.7/site-packages/flask_cors/extension.py", line 161, in wrapped_function
    return cors_after_request(app.make_response(f(*args, **kwargs)))
  File "/usr/local/lib/python3.7/site-packages/flask/app.py", line 1821, in handle_user_exception
    reraise(exc_type, exc_value, tb)
  File "/usr/local/lib/python3.7/site-packages/flask/_compat.py", line 39, in reraise
    raise value
  File "/usr/local/lib/python3.7/site-packages/flask/app.py", line 1950, in full_dispatch_request
    rv = self.dispatch_request()
  File "/usr/local/lib/python3.7/site-packages/flask/app.py", line 1936, in dispatch_request
    return self.view_functions[rule.endpoint](**req.view_args)
  File "/Users/user/Desktop/projectbackup/SchoolSystem/main.py", line 21, in login
    user = db.login(temp)
  File "/Users/user/Desktop/projectbackup/SchoolSystem/data/mongo.py", line 24, in login
    username = user.username
AttributeError: 'str' object has no attribute 'username'
2020-06-30 20:41:49,512 - werkzeug:113 - INFO - 127.0.0.1 - - [30/Jun/2020 20:41:49] "[35m[1mPOST /users HTTP/1.1[0m" 500 -
2020-06-30 20:43:09,955 - werkzeug:113 - INFO -  * Running on http://127.0.0.1:5000/ (Press CTRL+C to quit)
2020-06-30 20:43:18,455 - werkzeug:113 - INFO - 127.0.0.1 - - [30/Jun/2020 20:43:18] "[37mOPTIONS /users HTTP/1.1[0m" 200 -
2020-06-30 20:43:18,464 - werkzeug:113 - INFO - 127.0.0.1 - - [30/Jun/2020 20:43:18] "[31m[1mPOST /users HTTP/1.1[0m" 400 -
2020-06-30 20:45:11,412 - werkzeug:113 - INFO -  * Running on http://127.0.0.1:5000/ (Press CTRL+C to quit)
2020-06-30 20:45:30,668 - werkzeug:113 - INFO -  * Running on http://127.0.0.1:5000/ (Press CTRL+C to quit)
2020-06-30 20:45:39,400 - werkzeug:113 - INFO - 127.0.0.1 - - [30/Jun/2020 20:45:39] "[37mOPTIONS /users HTTP/1.1[0m" 200 -
2020-06-30 20:45:39,403 - werkzeug:113 - INFO - 127.0.0.1 - - [30/Jun/2020 20:45:39] "[31m[1mPOST /users HTTP/1.1[0m" 400 -
2020-06-30 20:46:44,784 - werkzeug:113 - INFO - 127.0.0.1 - - [30/Jun/2020 20:46:44] "[31m[1mPOST /users HTTP/1.1[0m" 400 -
2020-06-30 20:48:10,561 - werkzeug:113 - INFO -  * Running on http://127.0.0.1:5000/ (Press CTRL+C to quit)
2020-06-30 20:48:21,573 - werkzeug:113 - INFO - 127.0.0.1 - - [30/Jun/2020 20:48:21] "[37mOPTIONS /users HTTP/1.1[0m" 200 -
2020-06-30 20:48:21,575 - SchoolSystem.data.mongo:23 - INFO - Attempting to retrieve user from database
2020-06-30 20:48:21,576 - flask:1892 - ERROR - Exception on /users [POST]
Traceback (most recent call last):
  File "/usr/local/lib/python3.7/site-packages/flask/app.py", line 2447, in wsgi_app
    response = self.full_dispatch_request()
  File "/usr/local/lib/python3.7/site-packages/flask/app.py", line 1952, in full_dispatch_request
    rv = self.handle_user_exception(e)
  File "/usr/local/lib/python3.7/site-packages/flask_cors/extension.py", line 161, in wrapped_function
    return cors_after_request(app.make_response(f(*args, **kwargs)))
  File "/usr/local/lib/python3.7/site-packages/flask/app.py", line 1821, in handle_user_exception
    reraise(exc_type, exc_value, tb)
  File "/usr/local/lib/python3.7/site-packages/flask/_compat.py", line 39, in reraise
    raise value
  File "/usr/local/lib/python3.7/site-packages/flask/app.py", line 1950, in full_dispatch_request
    rv = self.dispatch_request()
  File "/usr/local/lib/python3.7/site-packages/flask/app.py", line 1936, in dispatch_request
    return self.view_functions[rule.endpoint](**req.view_args)
  File "/Users/user/Desktop/projectbackup/SchoolSystem/main.py", line 22, in login
    user = db.login(temp)
  File "/Users/user/Desktop/projectbackup/SchoolSystem/data/mongo.py", line 24, in login
    username = user.username
AttributeError: 'NoneType' object has no attribute 'username'
2020-06-30 20:48:21,583 - werkzeug:113 - INFO - 127.0.0.1 - - [30/Jun/2020 20:48:21] "[35m[1mPOST /users HTTP/1.1[0m" 500 -
